Workbook

Sheet Калькуляція ТД
F1: Додаток 4 | AM1: так
F2: до тендерної документації | AM2: ні
A3: КАЛЬКУЛЯЦІЯ
A4: розрахунку цін та загальної вартості надання послуг з навантаження, розвантаження, вивезення та перевезення деревини, Корсунь-Шевченківське надлісництво, Черкаська область (філія «Центральний лісовий офіс») | H4: В комірці C6 з випливаючого списку необхідно обрати варіант "так" якщо уччасник є платником ПДВ, і "Ні" якщо учасник не є платником ПДВ, в результаті автоматично підбиватиметься підсумкова сума з врахуванням ПДВ чи його відсутності
A6: Учасник є платником ПДВ | C6: так
A8: № з.п. | B8: Назва послуг | C8: Об`єм, м3 | D8: Коефіцієнт* | E8: Ціна, грн/м3 без ПДВ | F8: Вартість, грн без ПДВ**
A9: 1 | B9: Навантаження (перевантаження) деревини | D9: 0.22 | E9: =ROUND($F$59*D9,0) -> 0 | F9: =C9*E9 -> 0
A10: 2 | B10: Розвантаження деревини | D10: 0.189 | E10: =ROUND($F$59*D10,0) -> 0 | F10: =C10*E10 -> 0
A11: 3 | B11: Вивезення деревини з лісосік по лісовим дорогам (лісовою дорогою вважається маршрут, якщо не менше 2/3 його загальної протяжності відповідає характеристикам дороги спеціального призначення і класифікується як лісова дорога), за відстанню, км
A12: 3.1 | B12: 1 | D12: 0.397 | E12: =ROUND($F$59*D12,0) -> 0 | F12: =C12*E26 -> 0
A13: 3.2 | B13: 2 | D13: 0.397 | E13: =ROUND($F$59*D13,0) -> 0
A14: 3.3 | B14: 3 | D14: 0.397 | E14: =ROUND($F$59*D14,0) -> 0
A15: 3.4 | B15: 4 | D15: 0.446 | E15: =ROUND($F$59*D15,0) -> 0
A16: 3.5 | B16: 5 | D16: 0.48 | E16: =ROUND($F$59*D16,0) -> 0
A17: 3.6 | B17: 6 | D17: 0.511 | E17: =ROUND($F$59*D17,0) -> 0
A18: 3.7 | B18: 7 | D18: 0.54 | E18: =ROUND($F$59*D18,0) -> 0
A19: 3.8 | B19: 8 | D19: 0.569 | E19: =ROUND($F$59*D19,0) -> 0
A20: 3.9 | B20: 9 | D20: 0.594 | E20: =ROUND($F$59*D20,0) -> 0
A21: 3.10 | B21: 10 | D21: 0.617 | E21: =ROUND($F$59*D21,0) -> 0
A22: 3.11 | B22: 11 | D22: 0.634 | E22: =ROUND($F$59*D22,0) -> 0
A23: 3.12 | B23: 12 | D23: 0.649 | E23: =ROUND($F$59*D23,0) -> 0
A24: 3.13 | B24: 13 | D24: 0.663 | E24: =ROUND($F$59*D24,0) -> 0
... A26: 3.15 | B26: 15 | D26: 0.691 | E26: =ROUND($F$59*D26,0) -> 0
A27: 4 | B27: Перевезення деревини з верхніх та проміжних складів по дорогам загального користування (дорогою загального користування вважати маршрут, якщо не менше 2/3 його загальної протяжності відповідає вимогам, визначеним для доріг загального користування), за відстанню, км
A28: 4.1 | B28: до 4 км (включно) | D28: 0.417 | E28: =ROUND($F$59*D28,0) -> 0 | F28: =C28*E45 -> 0
A29: 4.2 | B29: від 5 до 9 км (включно) | D29: 0.451 | E29: =ROUND($F$59*D29,0) -> 0
A30: 4.3 | B30: від 10 до 14 км (включно) | D30: 0.486 | E30: =ROUND($F$59*D30,0) -> 0
A31: 4.4 | B31: від 15 до 19 км (включно) | D31: 0.52 | E31: =ROUND($F$59*D31,0) -> 0
A32: 4.5 | B32: від 20 до 24 км (включно) | D32: 0.554 | E32: =ROUND($F$59*D32,0) -> 0
A33: 4.6 | B33: від 25 до 29 км (включно) | D33: 0.589 | E33: =ROUND($F$59*D33,0) -> 0
A34: 4.7 | B34: від 30 до 34 км (включно) | D34: 0.623 | E34: =ROUND($F$59*D34,0) -> 0
A35: 4.8 | B35: від 35 до 39 км (включно) | D35: 0.657 | E35: =ROUND($F$59*D35,0) -> 0
A36: 4.9 | B36: від 40 до 44 км (включно) | D36: 0.691 | E36: =ROUND($F$59*D36,0) -> 0
A37: 4.10 | B37: від 45 до 49 км (включно) | D37: 0.726 | E37: =ROUND($F$59*D37,0) -> 0
A38: 4.11 | B38: від 50 до 54 км (включно) | D38: 0.76 | E38: =ROUND($F$59*D38,0) -> 0
A39: 4.12 | B39: від 55 до 59 км (включно) | D39: 0.794 | E39: =ROUND($F$59*D39,0) -> 0
A40: 4.13 | B40: від 60 до 64 км (включно) | D40: 0.829 | E40: =ROUND($F$59*D40,0) -> 0
... A45: 4.18 | B45: від 85 до 89 км (включно) | D45: 1 | E45: =ROUND($F$59*D45,0) -> 0
C46: Об`єм, м3 | D46: Коефіцієнт* | E46: Ціна, грн/м3*км, без ПДВ | F46: Вартість, грн без ПДВ**
A47: 5 | B47: Перевезення деревини з верхніх та проміжних складів по дорогам загального користування (дорогою загального користування вважати маршрут, якщо не менше 2/3 його загальної протяжності відповідає вимогам, визначеним для доріг загального користування) на відстань від 90 км | D47: 0.01057 | E47: =ROUND($F$59*D47,2) -> 0 | F47: =C47*E47*300 -> 0
...

Sheet Калькуляція Договір 2
F1: Додаток 2 | AF1: так
F2: до договору від ____. ____ 20___ р | AF2: ні
F3: №__________________________
A4: КАЛЬКУЛЯЦІЯ
A5: ='Калькуляція ТД'!A4 -> розрахунку цін та загальної вартості надання послуг з навантаження, розвантаження, вивезення та перевезення деревини, Корсунь-Шевченківське надлісництво, Черкаська область (філія «Центральний лісовий офіс»)
A7: Учасник є платником ПДВ | C7: ='Калькуляція ТД'!C6 -> так
A9: № з.п. | B9: Назва послуг | C9: Об`єм, м3 | D9: Коефіцієнт | E9: Ціна, грн/м3 без ПДВ | F9: Вартість, грн без ПДВ
A11: 1 | B11: Навантаження (перевантаження) деревини | C11: ='Калькуляція ТД'!C9 -> 0 | D11: 0.241 | E11: ='Калькуляція ТД'!E9 -> 0 | F11: =C11*E11 -> 0
A12: 2 | B12: Розвантаження деревини | C12: ='Калькуляція ТД'!C10 -> 0 | D12: 0.207 | E12: ='Калькуляція ТД'!E10 -> 0 | F12: =C12*E12 -> 0
A13: 3 | B13: Вивезення деревини з лісосік по лісовим дорогам (лісовою дорогою вважається маршрут, якщо не менше 2/3 його загальної протяжності відповідає характеристикам дороги спеціального призначення і класифікується як лісова дорога), за відстанню, км
A14: 3.1 | B14: 1 | C14: ='Калькуляція ТД'!C12 -> 0 | D14: 0.414 | E14: ='Калькуляція ТД'!E12 -> 0 | F14: =C14*E28 -> 0
A15: 3.2 | B15: 2 | D15: 0.414 | E15: ='Калькуляція ТД'!E13 -> 0
A16: 3.3 | B16: 3 | D16: 0.414 | E16: ='Калькуляція ТД'!E14 -> 0
A17: 3.4 | B17: 4 | D17: 0.466 | E17: ='Калькуляція ТД'!E15 -> 0
A18: 3.5 | B18: 5 | D18: 0.5 | E18: ='Калькуляція ТД'!E16 -> 0
A19: 3.6 | B19: 6 | D19: 0.534 | E19: ='Калькуляція ТД'!E17 -> 0
A20: 3.7 | B20: 7 | D20: 0.559 | E20: ='Калькуляція ТД'!E18 -> 0
A21: 3.8 | B21: 8 | D21: 0.583 | E21: ='Калькуляція ТД'!E19 -> 0
A22: 3.9 | B22: 9 | D22: 0.6 | E22: ='Калькуляція ТД'!E20 -> 0
A23: 3.10 | B23: 10 | D23: 0.614 | E23: ='Калькуляція ТД'!E21 -> 0
A24: 3.11 | B24: 11 | D24: 0.631 | E24: ='Калькуляція ТД'!E22 -> 0
A25: 3.12 | B25: 12 | D25: 0.641 | E25: ='Калькуляція ТД'!E23 -> 0
A26: 3.13 | B26: 13 | D26: 0.652 | E26: ='Калькуляція ТД'!E24 -> 0
... A28: 3.15 | B28: 15 | D28: 0.672 | E28: ='Калькуляція ТД'!E26 -> 0
A29: 4 | B29: Перевезення деревини з верхніх та проміжних складів по дорогам загального користування (дорогою загального користування вважати маршрут, якщо не менше 2/3 його загальної протяжності відповідає вимогам, визначеним для доріг загального користування), за відстанню, км
A30: 4.1 | B30: до 4 км (включно) | C30: ='Калькуляція ТД'!C28 -> 0 | D30: 0.241 | E30: ='Калькуляція ТД'!E28 -> 0 | F30: =C30*E47 -> 0
A31: 4.2 | B31: від 5 до 9 км (включно) | D31: 0.31 | E31: ='Калькуляція ТД'!E29 -> 0
A32: 4.3 | B32: від 10 до 14 км (включно) | D32: 0.379 | E32: ='Калькуляція ТД'!E30 -> 0
A33: 4.4 | B33: від 15 до 19 км (включно) | D33: 0.448 | E33: ='Калькуляція ТД'!E31 -> 0
A34: 4.5 | B34: від 20 до 24 км (включно) | D34: 0.517 | E34: ='Калькуляція ТД'!E32 -> 0
A35: 4.6 | B35: від 25 до 29 км (включно) | D35: 0.586 | E35: ='Калькуляція ТД'!E33 -> 0
A36: 4.7 | B36: від 30 до 34 км (включно) | D36: 0.621 | E36: ='Калькуляція ТД'!E34 -> 0
A37: 4.8 | B37: від 35 до 39 км (включно) | D37: 0.655 | E37: ='Калькуляція ТД'!E35 -> 0
A38: 4.9 | B38: від 40 до 44 км (включно) | D38: 0.69 | E38: ='Калькуляція ТД'!E36 -> 0
A39: 4.10 | B39: від 45 до 49 км (включно) | D39: 0.724 | E39: ='Калькуляція ТД'!E37 -> 0
A40: 4.11 | B40: від 50 до 54 км (включно) | D40: 0.759 | E40: ='Калькуляція ТД'!E38 -> 0
A41: 4.12 | B41: від 55 до 59 км (включно) | D41: 0.793 | E41: ='Калькуляція ТД'!E39 -> 0
A42: 4.13 | B42: від 60 до 64 км (включно) | D42: 0.828 | E42: ='Калькуляція ТД'!E40 -> 0
... A47: 4.18 | B47: від 85 до 89 км (включно) | D47: 1 | E47: ='Калькуляція ТД'!E45 -> 0
C48: Об`єм, м3 | D48: Коефіцієнт | E48: Ціна, грн/м3*км, без ПДВ | F48: Вартість, грн без ПДВ
...
